[2025-07-30T11:03:39.929+0000] {local_task_job_runner.py:120} INFO - ::group::Pre task execution logs
[2025-07-30T11:03:39.963+0000] {taskinstance.py:2073} INFO - Dependencies all met for dep_context=non-requeueable deps ti=<TaskInstance: financial_etl_pipeline.load_data_to_postgres manual__2025-07-30T11:03:29.225286+00:00 [queued]>
[2025-07-30T11:03:39.974+0000] {taskinstance.py:2073} INFO - Dependencies all met for dep_context=requeueable deps ti=<TaskInstance: financial_etl_pipeline.load_data_to_postgres manual__2025-07-30T11:03:29.225286+00:00 [queued]>
[2025-07-30T11:03:39.975+0000] {taskinstance.py:2303} INFO - Starting attempt 1 of 1
[2025-07-30T11:03:40.140+0000] {taskinstance.py:2327} INFO - Executing <Task(PythonOperator): load_data_to_postgres> on 2025-07-30 11:03:29.225286+00:00
[2025-07-30T11:03:40.153+0000] {logging_mixin.py:188} WARNING - /home/***/.local/lib/python3.12/site-packages/***/task/task_runner/standard_task_runner.py:61 DeprecationWarning: This process (pid=214) is multi-threaded, use of fork() may lead to deadlocks in the child.
[2025-07-30T11:03:40.151+0000] {standard_task_runner.py:90} INFO - Running: ['***', 'tasks', 'run', 'financial_etl_pipeline', 'load_data_to_postgres', 'manual__2025-07-30T11:03:29.225286+00:00', '--job-id', '232', '--raw', '--subdir', 'DAGS_FOLDER/financial_etl_dag.py', '--cfg-path', '/tmp/tmpxqil44qj']
[2025-07-30T11:03:40.155+0000] {standard_task_runner.py:63} INFO - Started process 216 to run task
[2025-07-30T11:03:40.155+0000] {standard_task_runner.py:91} INFO - Job 232: Subtask load_data_to_postgres
[2025-07-30T11:03:40.257+0000] {task_command.py:426} INFO - Running <TaskInstance: financial_etl_pipeline.load_data_to_postgres manual__2025-07-30T11:03:29.225286+00:00 [running]> on host 9c353dd7cf4b
[2025-07-30T11:03:40.367+0000] {taskinstance.py:2644} INFO - Exporting env vars: AIRFLOW_CTX_DAG_OWNER='***' AIRFLOW_CTX_DAG_ID='financial_etl_pipeline' AIRFLOW_CTX_TASK_ID='load_data_to_postgres' AIRFLOW_CTX_EXECUTION_DATE='2025-07-30T11:03:29.225286+00:00' AIRFLOW_CTX_TRY_NUMBER='1' AIRFLOW_CTX_DAG_RUN_ID='manual__2025-07-30T11:03:29.225286+00:00'
[2025-07-30T11:03:40.369+0000] {taskinstance.py:430} INFO - ::endgroup::
[2025-07-30T11:03:40.422+0000] {taskinstance.py:441} INFO - ::group::Post task execution logs
[2025-07-30T11:03:40.423+0000] {taskinstance.py:2890} ERROR - Task failed with exception
Traceback (most recent call last):
  File "/home/airflow/.local/lib/python3.12/site-packages/airflow/models/taskinstance.py", line 465, in _execute_task
    result = _execute_callable(context=context, **execute_callable_kwargs)
             ^^^^^^^^^^^^^^^^^^^^^^^^^^^^^^^^^^^^^^^^^^^^^^^^^^^^^^^^^^^^^
  File "/home/airflow/.local/lib/python3.12/site-packages/airflow/models/taskinstance.py", line 432, in _execute_callable
    return execute_callable(context=context, **execute_callable_kwargs)
           ^^^^^^^^^^^^^^^^^^^^^^^^^^^^^^^^^^^^^^^^^^^^^^^^^^^^^^^^^^^^
  File "/home/airflow/.local/lib/python3.12/site-packages/airflow/models/baseoperator.py", line 400, in wrapper
    return func(self, *args, **kwargs)
           ^^^^^^^^^^^^^^^^^^^^^^^^^^^
  File "/home/airflow/.local/lib/python3.12/site-packages/airflow/operators/python.py", line 235, in execute
    return_value = self.execute_callable()
                   ^^^^^^^^^^^^^^^^^^^^^^^
  File "/home/airflow/.local/lib/python3.12/site-packages/airflow/operators/python.py", line 252, in execute_callable
    return self.python_callable(*self.op_args, **self.op_kwargs)
           ^^^^^^^^^^^^^^^^^^^^^^^^^^^^^^^^^^^^^^^^^^^^^^^^^^^^^
  File "/opt/airflow/dags/financial_etl_dag.py", line 76, in load_data_to_postgres
    cursor.execute("""
psycopg2.errors.UndefinedColumn: column "amount_inr" of relation "transactions" does not exist
LINE 2: ...mount, currency, timestamp, merchant, fraud_flag, amount_inr...
                                                             ^

[2025-07-30T11:03:40.450+0000] {taskinstance.py:1205} INFO - Marking task as FAILED. dag_id=financial_etl_pipeline, task_id=load_data_to_postgres, execution_date=20250730T110329, start_date=20250730T110339, end_date=20250730T110340
[2025-07-30T11:03:40.478+0000] {standard_task_runner.py:110} ERROR - Failed to execute job 232 for task load_data_to_postgres (column "amount_inr" of relation "transactions" does not exist
LINE 2: ...mount, currency, timestamp, merchant, fraud_flag, amount_inr...
                                                             ^
; 216)
[2025-07-30T11:03:40.490+0000] {local_task_job_runner.py:240} INFO - Task exited with return code 1
[2025-07-30T11:03:40.519+0000] {taskinstance.py:3482} INFO - 0 downstream tasks scheduled from follow-on schedule check
[2025-07-30T11:03:40.525+0000] {local_task_job_runner.py:222} INFO - ::endgroup::
