[2025-07-28T18:41:10.106+0000] {local_task_job_runner.py:120} INFO - ::group::Pre task execution logs
[2025-07-28T18:41:10.154+0000] {taskinstance.py:2073} INFO - Dependencies all met for dep_context=non-requeueable deps ti=<TaskInstance: financial_etl_pipeline.aggregate_monthly_summary manual__2025-07-28T18:41:01.881371+00:00 [queued]>
[2025-07-28T18:41:10.168+0000] {taskinstance.py:2073} INFO - Dependencies all met for dep_context=requeueable deps ti=<TaskInstance: financial_etl_pipeline.aggregate_monthly_summary manual__2025-07-28T18:41:01.881371+00:00 [queued]>
[2025-07-28T18:41:10.170+0000] {taskinstance.py:2303} INFO - Starting attempt 1 of 1
[2025-07-28T18:41:10.373+0000] {taskinstance.py:2327} INFO - Executing <Task(PythonOperator): aggregate_monthly_summary> on 2025-07-28 18:41:01.881371+00:00
[2025-07-28T18:41:10.392+0000] {standard_task_runner.py:90} INFO - Running: ['***', 'tasks', 'run', 'financial_etl_pipeline', 'aggregate_monthly_summary', 'manual__2025-07-28T18:41:01.881371+00:00', '--job-id', '155', '--raw', '--subdir', 'DAGS_FOLDER/financial_etl_dag.py', '--cfg-path', '/tmp/tmp8ep8iatm']
[2025-07-28T18:41:10.395+0000] {standard_task_runner.py:91} INFO - Job 155: Subtask aggregate_monthly_summary
[2025-07-28T18:41:10.395+0000] {logging_mixin.py:188} WARNING - /home/***/.local/lib/python3.12/site-packages/***/task/task_runner/standard_task_runner.py:61 DeprecationWarning: This process (pid=239) is multi-threaded, use of fork() may lead to deadlocks in the child.
[2025-07-28T18:41:10.396+0000] {standard_task_runner.py:63} INFO - Started process 241 to run task
[2025-07-28T18:41:10.481+0000] {task_command.py:426} INFO - Running <TaskInstance: financial_etl_pipeline.aggregate_monthly_summary manual__2025-07-28T18:41:01.881371+00:00 [running]> on host 7815b21b8845
[2025-07-28T18:41:10.573+0000] {taskinstance.py:2644} INFO - Exporting env vars: AIRFLOW_CTX_DAG_OWNER='***' AIRFLOW_CTX_DAG_ID='financial_etl_pipeline' AIRFLOW_CTX_TASK_ID='aggregate_monthly_summary' AIRFLOW_CTX_EXECUTION_DATE='2025-07-28T18:41:01.881371+00:00' AIRFLOW_CTX_TRY_NUMBER='1' AIRFLOW_CTX_DAG_RUN_ID='manual__2025-07-28T18:41:01.881371+00:00'
[2025-07-28T18:41:10.574+0000] {taskinstance.py:430} INFO - ::endgroup::
[2025-07-28T18:41:10.605+0000] {taskinstance.py:441} INFO - ::group::Post task execution logs
[2025-07-28T18:41:10.606+0000] {taskinstance.py:2890} ERROR - Task failed with exception
Traceback (most recent call last):
  File "/home/airflow/.local/lib/python3.12/site-packages/airflow/models/taskinstance.py", line 465, in _execute_task
    result = _execute_callable(context=context, **execute_callable_kwargs)
             ^^^^^^^^^^^^^^^^^^^^^^^^^^^^^^^^^^^^^^^^^^^^^^^^^^^^^^^^^^^^^
  File "/home/airflow/.local/lib/python3.12/site-packages/airflow/models/taskinstance.py", line 432, in _execute_callable
    return execute_callable(context=context, **execute_callable_kwargs)
           ^^^^^^^^^^^^^^^^^^^^^^^^^^^^^^^^^^^^^^^^^^^^^^^^^^^^^^^^^^^^
  File "/home/airflow/.local/lib/python3.12/site-packages/airflow/models/baseoperator.py", line 400, in wrapper
    return func(self, *args, **kwargs)
           ^^^^^^^^^^^^^^^^^^^^^^^^^^^
  File "/home/airflow/.local/lib/python3.12/site-packages/airflow/operators/python.py", line 235, in execute
    return_value = self.execute_callable()
                   ^^^^^^^^^^^^^^^^^^^^^^^
  File "/home/airflow/.local/lib/python3.12/site-packages/airflow/operators/python.py", line 252, in execute_callable
    return self.python_callable(*self.op_args, **self.op_kwargs)
           ^^^^^^^^^^^^^^^^^^^^^^^^^^^^^^^^^^^^^^^^^^^^^^^^^^^^^
  File "/opt/airflow/dags/financial_etl_dag.py", line 79, in aggregate_monthly_summary
    cursor.execute("""
psycopg2.errors.UndefinedColumn: column "date" does not exist
LINE 4:             TO_CHAR(TO_DATE(date, 'YYYY-MM-DD'), 'YYYY-MM') ...
                                    ^

[2025-07-28T18:41:10.625+0000] {taskinstance.py:1205} INFO - Marking task as FAILED. dag_id=financial_etl_pipeline, task_id=aggregate_monthly_summary, execution_date=20250728T184101, start_date=20250728T184110, end_date=20250728T184110
[2025-07-28T18:41:10.639+0000] {standard_task_runner.py:110} ERROR - Failed to execute job 155 for task aggregate_monthly_summary (column "date" does not exist
LINE 4:             TO_CHAR(TO_DATE(date, 'YYYY-MM-DD'), 'YYYY-MM') ...
                                    ^
; 241)
[2025-07-28T18:41:10.650+0000] {local_task_job_runner.py:240} INFO - Task exited with return code 1
[2025-07-28T18:41:10.665+0000] {taskinstance.py:3482} INFO - 0 downstream tasks scheduled from follow-on schedule check
[2025-07-28T18:41:10.668+0000] {local_task_job_runner.py:222} INFO - ::endgroup::
