[2025-07-28T12:46:09.997+0000] {local_task_job_runner.py:120} INFO - ::group::Pre task execution logs
[2025-07-28T12:46:11.781+0000] {taskinstance.py:2073} INFO - Dependencies all met for dep_context=non-requeueable deps ti=<TaskInstance: financial_etl_dag.load_to_postgres manual__2025-07-28T12:43:36.590512+00:00 [queued]>
[2025-07-28T12:46:11.825+0000] {taskinstance.py:2073} INFO - Dependencies all met for dep_context=requeueable deps ti=<TaskInstance: financial_etl_dag.load_to_postgres manual__2025-07-28T12:43:36.590512+00:00 [queued]>
[2025-07-28T12:46:11.829+0000] {taskinstance.py:2303} INFO - Starting attempt 1 of 2
[2025-07-28T12:46:11.972+0000] {taskinstance.py:2327} INFO - Executing <Task(PythonOperator): load_to_postgres> on 2025-07-28 12:43:36.590512+00:00
[2025-07-28T12:46:12.111+0000] {logging_mixin.py:188} WARNING - /home/***/.local/lib/python3.12/site-packages/***/task/task_runner/standard_task_runner.py:61 DeprecationWarning: This process (pid=449) is multi-threaded, use of fork() may lead to deadlocks in the child.
[2025-07-28T12:46:12.143+0000] {standard_task_runner.py:63} INFO - Started process 459 to run task
[2025-07-28T12:46:12.131+0000] {standard_task_runner.py:90} INFO - Running: ['***', 'tasks', 'run', 'financial_etl_dag', 'load_to_postgres', 'manual__2025-07-28T12:43:36.590512+00:00', '--job-id', '105', '--raw', '--subdir', 'DAGS_FOLDER/financial_etl_dag.py', '--cfg-path', '/tmp/tmp5sy0_eht']
[2025-07-28T12:46:12.174+0000] {standard_task_runner.py:91} INFO - Job 105: Subtask load_to_postgres
[2025-07-28T12:46:12.608+0000] {task_command.py:426} INFO - Running <TaskInstance: financial_etl_dag.load_to_postgres manual__2025-07-28T12:43:36.590512+00:00 [running]> on host 3fd530ef422e
[2025-07-28T12:46:13.105+0000] {taskinstance.py:2644} INFO - Exporting env vars: AIRFLOW_CTX_DAG_OWNER='***' AIRFLOW_CTX_DAG_ID='financial_etl_dag' AIRFLOW_CTX_TASK_ID='load_to_postgres' AIRFLOW_CTX_EXECUTION_DATE='2025-07-28T12:43:36.590512+00:00' AIRFLOW_CTX_TRY_NUMBER='1' AIRFLOW_CTX_DAG_RUN_ID='manual__2025-07-28T12:43:36.590512+00:00'
[2025-07-28T12:46:13.109+0000] {taskinstance.py:430} INFO - ::endgroup::
[2025-07-28T12:46:13.184+0000] {taskinstance.py:441} INFO - ::group::Post task execution logs
[2025-07-28T12:46:13.186+0000] {taskinstance.py:2890} ERROR - Task failed with exception
Traceback (most recent call last):
  File "/home/airflow/.local/lib/python3.12/site-packages/airflow/models/taskinstance.py", line 465, in _execute_task
    result = _execute_callable(context=context, **execute_callable_kwargs)
             ^^^^^^^^^^^^^^^^^^^^^^^^^^^^^^^^^^^^^^^^^^^^^^^^^^^^^^^^^^^^^
  File "/home/airflow/.local/lib/python3.12/site-packages/airflow/models/taskinstance.py", line 432, in _execute_callable
    return execute_callable(context=context, **execute_callable_kwargs)
           ^^^^^^^^^^^^^^^^^^^^^^^^^^^^^^^^^^^^^^^^^^^^^^^^^^^^^^^^^^^^
  File "/home/airflow/.local/lib/python3.12/site-packages/airflow/models/baseoperator.py", line 400, in wrapper
    return func(self, *args, **kwargs)
           ^^^^^^^^^^^^^^^^^^^^^^^^^^^
  File "/home/airflow/.local/lib/python3.12/site-packages/airflow/operators/python.py", line 235, in execute
    return_value = self.execute_callable()
                   ^^^^^^^^^^^^^^^^^^^^^^^
  File "/home/airflow/.local/lib/python3.12/site-packages/airflow/operators/python.py", line 252, in execute_callable
    return self.python_callable(*self.op_args, **self.op_kwargs)
           ^^^^^^^^^^^^^^^^^^^^^^^^^^^^^^^^^^^^^^^^^^^^^^^^^^^^^
  File "/opt/airflow/dags/financial_etl_dag.py", line 64, in load_to_postgres
    df = pd.read_pickle(os.path.join(BASE_PATH, 'cleaned_data.pkl'))
         ^^^^^^^^^^^^^^^^^^^^^^^^^^^^^^^^^^^^^^^^^^^^^^^^^^^^^^^^^^^
  File "/home/airflow/.local/lib/python3.12/site-packages/pandas/io/pickle.py", line 189, in read_pickle
    with get_handle(
         ^^^^^^^^^^^
  File "/home/airflow/.local/lib/python3.12/site-packages/pandas/io/common.py", line 872, in get_handle
    handle = open(handle, ioargs.mode)
             ^^^^^^^^^^^^^^^^^^^^^^^^^
FileNotFoundError: [Errno 2] No such file or directory: '/opt/airflow/dags/files/cleaned_data.pkl'
[2025-07-28T12:46:13.234+0000] {taskinstance.py:1205} INFO - Marking task as UP_FOR_RETRY. dag_id=financial_etl_dag, task_id=load_to_postgres, execution_date=20250728T124336, start_date=20250728T124611, end_date=20250728T124613
[2025-07-28T12:46:13.260+0000] {standard_task_runner.py:110} ERROR - Failed to execute job 105 for task load_to_postgres ([Errno 2] No such file or directory: '/opt/airflow/dags/files/cleaned_data.pkl'; 459)
[2025-07-28T12:46:13.317+0000] {local_task_job_runner.py:240} INFO - Task exited with return code 1
[2025-07-28T12:46:13.363+0000] {taskinstance.py:3482} INFO - 0 downstream tasks scheduled from follow-on schedule check
[2025-07-28T12:46:13.372+0000] {local_task_job_runner.py:222} INFO - ::endgroup::
