[2025-07-30T11:11:56.452+0000] {local_task_job_runner.py:120} INFO - ::group::Pre task execution logs
[2025-07-30T11:11:56.496+0000] {taskinstance.py:2073} INFO - Dependencies all met for dep_context=non-requeueable deps ti=<TaskInstance: financial_etl_pipeline.aggregate_monthly_summary manual__2025-07-30T11:11:47.518903+00:00 [queued]>
[2025-07-30T11:11:56.509+0000] {taskinstance.py:2073} INFO - Dependencies all met for dep_context=requeueable deps ti=<TaskInstance: financial_etl_pipeline.aggregate_monthly_summary manual__2025-07-30T11:11:47.518903+00:00 [queued]>
[2025-07-30T11:11:56.510+0000] {taskinstance.py:2303} INFO - Starting attempt 1 of 1
[2025-07-30T11:11:56.701+0000] {taskinstance.py:2327} INFO - Executing <Task(PythonOperator): aggregate_monthly_summary> on 2025-07-30 11:11:47.518903+00:00
[2025-07-30T11:11:56.713+0000] {standard_task_runner.py:90} INFO - Running: ['***', 'tasks', 'run', 'financial_etl_pipeline', 'aggregate_monthly_summary', 'manual__2025-07-30T11:11:47.518903+00:00', '--job-id', '240', '--raw', '--subdir', 'DAGS_FOLDER/financial_etl_dag.py', '--cfg-path', '/tmp/tmpprmllyec']
[2025-07-30T11:11:56.717+0000] {standard_task_runner.py:91} INFO - Job 240: Subtask aggregate_monthly_summary
[2025-07-30T11:11:56.718+0000] {logging_mixin.py:188} WARNING - /home/***/.local/lib/python3.12/site-packages/***/task/task_runner/standard_task_runner.py:61 DeprecationWarning: This process (pid=568) is multi-threaded, use of fork() may lead to deadlocks in the child.
[2025-07-30T11:11:56.718+0000] {standard_task_runner.py:63} INFO - Started process 573 to run task
[2025-07-30T11:11:56.815+0000] {task_command.py:426} INFO - Running <TaskInstance: financial_etl_pipeline.aggregate_monthly_summary manual__2025-07-30T11:11:47.518903+00:00 [running]> on host 9c353dd7cf4b
[2025-07-30T11:11:56.915+0000] {taskinstance.py:2644} INFO - Exporting env vars: AIRFLOW_CTX_DAG_OWNER='***' AIRFLOW_CTX_DAG_ID='financial_etl_pipeline' AIRFLOW_CTX_TASK_ID='aggregate_monthly_summary' AIRFLOW_CTX_EXECUTION_DATE='2025-07-30T11:11:47.518903+00:00' AIRFLOW_CTX_TRY_NUMBER='1' AIRFLOW_CTX_DAG_RUN_ID='manual__2025-07-30T11:11:47.518903+00:00'
[2025-07-30T11:11:56.917+0000] {taskinstance.py:430} INFO - ::endgroup::
[2025-07-30T11:11:56.946+0000] {taskinstance.py:441} INFO - ::group::Post task execution logs
[2025-07-30T11:11:56.947+0000] {taskinstance.py:2890} ERROR - Task failed with exception
Traceback (most recent call last):
  File "/home/airflow/.local/lib/python3.12/site-packages/airflow/models/taskinstance.py", line 465, in _execute_task
    result = _execute_callable(context=context, **execute_callable_kwargs)
             ^^^^^^^^^^^^^^^^^^^^^^^^^^^^^^^^^^^^^^^^^^^^^^^^^^^^^^^^^^^^^
  File "/home/airflow/.local/lib/python3.12/site-packages/airflow/models/taskinstance.py", line 432, in _execute_callable
    return execute_callable(context=context, **execute_callable_kwargs)
           ^^^^^^^^^^^^^^^^^^^^^^^^^^^^^^^^^^^^^^^^^^^^^^^^^^^^^^^^^^^^
  File "/home/airflow/.local/lib/python3.12/site-packages/airflow/models/baseoperator.py", line 400, in wrapper
    return func(self, *args, **kwargs)
           ^^^^^^^^^^^^^^^^^^^^^^^^^^^
  File "/home/airflow/.local/lib/python3.12/site-packages/airflow/operators/python.py", line 235, in execute
    return_value = self.execute_callable()
                   ^^^^^^^^^^^^^^^^^^^^^^^
  File "/home/airflow/.local/lib/python3.12/site-packages/airflow/operators/python.py", line 252, in execute_callable
    return self.python_callable(*self.op_args, **self.op_kwargs)
           ^^^^^^^^^^^^^^^^^^^^^^^^^^^^^^^^^^^^^^^^^^^^^^^^^^^^^
  File "/opt/airflow/dags/financial_etl_dag.py", line 102, in aggregate_monthly_summary
    cursor.execute("""
psycopg2.errors.UndefinedColumn: column "merchant" of relation "monthly_summary" does not exist
LINE 2:         INSERT INTO monthly_summary (month, merchant, total_...
                                                    ^

[2025-07-30T11:11:56.973+0000] {taskinstance.py:1205} INFO - Marking task as FAILED. dag_id=financial_etl_pipeline, task_id=aggregate_monthly_summary, execution_date=20250730T111147, start_date=20250730T111156, end_date=20250730T111156
[2025-07-30T11:11:56.995+0000] {standard_task_runner.py:110} ERROR - Failed to execute job 240 for task aggregate_monthly_summary (column "merchant" of relation "monthly_summary" does not exist
LINE 2:         INSERT INTO monthly_summary (month, merchant, total_...
                                                    ^
; 573)
[2025-07-30T11:11:57.016+0000] {local_task_job_runner.py:240} INFO - Task exited with return code 1
[2025-07-30T11:11:57.047+0000] {taskinstance.py:3482} INFO - 0 downstream tasks scheduled from follow-on schedule check
[2025-07-30T11:11:57.051+0000] {local_task_job_runner.py:222} INFO - ::endgroup::
