[2025-07-28T18:47:01.727+0000] {local_task_job_runner.py:120} INFO - ::group::Pre task execution logs
[2025-07-28T18:47:01.791+0000] {taskinstance.py:2073} INFO - Dependencies all met for dep_context=non-requeueable deps ti=<TaskInstance: financial_etl_pipeline.aggregate_monthly_summary manual__2025_07_28_agg [queued]>
[2025-07-28T18:47:01.809+0000] {taskinstance.py:2073} INFO - Dependencies all met for dep_context=requeueable deps ti=<TaskInstance: financial_etl_pipeline.aggregate_monthly_summary manual__2025_07_28_agg [queued]>
[2025-07-28T18:47:01.811+0000] {taskinstance.py:2303} INFO - Starting attempt 1 of 1
[2025-07-28T18:47:02.039+0000] {taskinstance.py:2327} INFO - Executing <Task(PythonOperator): aggregate_monthly_summary> on 2025-07-28 18:46:50+00:00
[2025-07-28T18:47:02.054+0000] {standard_task_runner.py:90} INFO - Running: ['***', 'tasks', 'run', 'financial_etl_pipeline', 'aggregate_monthly_summary', 'manual__2025_07_28_agg', '--job-id', '161', '--raw', '--subdir', 'DAGS_FOLDER/financial_etl_dag.py', '--cfg-path', '/tmp/tmpi83yw9m3']
[2025-07-28T18:47:02.060+0000] {logging_mixin.py:188} WARNING - /home/***/.local/lib/python3.12/site-packages/***/task/task_runner/standard_task_runner.py:61 DeprecationWarning: This process (pid=493) is multi-threaded, use of fork() may lead to deadlocks in the child.
[2025-07-28T18:47:02.061+0000] {standard_task_runner.py:91} INFO - Job 161: Subtask aggregate_monthly_summary
[2025-07-28T18:47:02.062+0000] {standard_task_runner.py:63} INFO - Started process 495 to run task
[2025-07-28T18:47:02.179+0000] {task_command.py:426} INFO - Running <TaskInstance: financial_etl_pipeline.aggregate_monthly_summary manual__2025_07_28_agg [running]> on host 7815b21b8845
[2025-07-28T18:47:02.324+0000] {taskinstance.py:2644} INFO - Exporting env vars: AIRFLOW_CTX_DAG_OWNER='***' AIRFLOW_CTX_DAG_ID='financial_etl_pipeline' AIRFLOW_CTX_TASK_ID='aggregate_monthly_summary' AIRFLOW_CTX_EXECUTION_DATE='2025-07-28T18:46:50+00:00' AIRFLOW_CTX_TRY_NUMBER='1' AIRFLOW_CTX_DAG_RUN_ID='manual__2025_07_28_agg'
[2025-07-28T18:47:02.326+0000] {taskinstance.py:430} INFO - ::endgroup::
[2025-07-28T18:47:02.382+0000] {taskinstance.py:441} INFO - ::group::Post task execution logs
[2025-07-28T18:47:02.384+0000] {taskinstance.py:2890} ERROR - Task failed with exception
Traceback (most recent call last):
  File "/home/airflow/.local/lib/python3.12/site-packages/airflow/models/taskinstance.py", line 465, in _execute_task
    result = _execute_callable(context=context, **execute_callable_kwargs)
             ^^^^^^^^^^^^^^^^^^^^^^^^^^^^^^^^^^^^^^^^^^^^^^^^^^^^^^^^^^^^^
  File "/home/airflow/.local/lib/python3.12/site-packages/airflow/models/taskinstance.py", line 432, in _execute_callable
    return execute_callable(context=context, **execute_callable_kwargs)
           ^^^^^^^^^^^^^^^^^^^^^^^^^^^^^^^^^^^^^^^^^^^^^^^^^^^^^^^^^^^^
  File "/home/airflow/.local/lib/python3.12/site-packages/airflow/models/baseoperator.py", line 400, in wrapper
    return func(self, *args, **kwargs)
           ^^^^^^^^^^^^^^^^^^^^^^^^^^^
  File "/home/airflow/.local/lib/python3.12/site-packages/airflow/operators/python.py", line 235, in execute
    return_value = self.execute_callable()
                   ^^^^^^^^^^^^^^^^^^^^^^^
  File "/home/airflow/.local/lib/python3.12/site-packages/airflow/operators/python.py", line 252, in execute_callable
    return self.python_callable(*self.op_args, **self.op_kwargs)
           ^^^^^^^^^^^^^^^^^^^^^^^^^^^^^^^^^^^^^^^^^^^^^^^^^^^^^
  File "/opt/airflow/dags/financial_etl_dag.py", line 79, in aggregate_monthly_summary
    cursor.execute("""
psycopg2.errors.UndefinedColumn: column "date" does not exist
LINE 4:             TO_CHAR(TO_DATE(date, 'YYYY-MM-DD'), 'YYYY-MM') ...
                                    ^

[2025-07-28T18:47:02.419+0000] {taskinstance.py:1205} INFO - Marking task as FAILED. dag_id=financial_etl_pipeline, task_id=aggregate_monthly_summary, execution_date=20250728T184650, start_date=20250728T184701, end_date=20250728T184702
[2025-07-28T18:47:02.445+0000] {standard_task_runner.py:110} ERROR - Failed to execute job 161 for task aggregate_monthly_summary (column "date" does not exist
LINE 4:             TO_CHAR(TO_DATE(date, 'YYYY-MM-DD'), 'YYYY-MM') ...
                                    ^
; 495)
[2025-07-28T18:47:02.478+0000] {local_task_job_runner.py:240} INFO - Task exited with return code 1
[2025-07-28T18:47:02.507+0000] {taskinstance.py:3482} INFO - 0 downstream tasks scheduled from follow-on schedule check
[2025-07-28T18:47:02.512+0000] {local_task_job_runner.py:222} INFO - ::endgroup::
