[2025-07-28T18:19:11.790+0000] {local_task_job_runner.py:120} INFO - ::group::Pre task execution logs
[2025-07-28T18:19:11.817+0000] {taskinstance.py:2073} INFO - Dependencies all met for dep_context=non-requeueable deps ti=<TaskInstance: financial_etl_pipeline.aggregate_monthly_summary manual__2025-07-28T18:19:03.874382+00:00 [queued]>
[2025-07-28T18:19:11.825+0000] {taskinstance.py:2073} INFO - Dependencies all met for dep_context=requeueable deps ti=<TaskInstance: financial_etl_pipeline.aggregate_monthly_summary manual__2025-07-28T18:19:03.874382+00:00 [queued]>
[2025-07-28T18:19:11.826+0000] {taskinstance.py:2303} INFO - Starting attempt 1 of 1
[2025-07-28T18:19:11.958+0000] {taskinstance.py:2327} INFO - Executing <Task(PythonOperator): aggregate_monthly_summary> on 2025-07-28 18:19:03.874382+00:00
[2025-07-28T18:19:11.968+0000] {standard_task_runner.py:90} INFO - Running: ['***', 'tasks', 'run', 'financial_etl_pipeline', 'aggregate_monthly_summary', 'manual__2025-07-28T18:19:03.874382+00:00', '--job-id', '133', '--raw', '--subdir', 'DAGS_FOLDER/financial_etl_dag.py', '--cfg-path', '/tmp/tmp79394ur2']
[2025-07-28T18:19:11.971+0000] {logging_mixin.py:188} WARNING - /home/***/.local/lib/python3.12/site-packages/***/task/task_runner/standard_task_runner.py:61 DeprecationWarning: This process (pid=9511) is multi-threaded, use of fork() may lead to deadlocks in the child.
[2025-07-28T18:19:11.971+0000] {standard_task_runner.py:91} INFO - Job 133: Subtask aggregate_monthly_summary
[2025-07-28T18:19:11.972+0000] {standard_task_runner.py:63} INFO - Started process 9513 to run task
[2025-07-28T18:19:12.045+0000] {task_command.py:426} INFO - Running <TaskInstance: financial_etl_pipeline.aggregate_monthly_summary manual__2025-07-28T18:19:03.874382+00:00 [running]> on host c9a4a3294b33
[2025-07-28T18:19:12.115+0000] {taskinstance.py:2644} INFO - Exporting env vars: AIRFLOW_CTX_DAG_OWNER='***' AIRFLOW_CTX_DAG_ID='financial_etl_pipeline' AIRFLOW_CTX_TASK_ID='aggregate_monthly_summary' AIRFLOW_CTX_EXECUTION_DATE='2025-07-28T18:19:03.874382+00:00' AIRFLOW_CTX_TRY_NUMBER='1' AIRFLOW_CTX_DAG_RUN_ID='manual__2025-07-28T18:19:03.874382+00:00'
[2025-07-28T18:19:12.117+0000] {taskinstance.py:430} INFO - ::endgroup::
[2025-07-28T18:19:12.144+0000] {taskinstance.py:441} INFO - ::group::Post task execution logs
[2025-07-28T18:19:12.145+0000] {taskinstance.py:2890} ERROR - Task failed with exception
Traceback (most recent call last):
  File "/home/airflow/.local/lib/python3.12/site-packages/airflow/models/taskinstance.py", line 465, in _execute_task
    result = _execute_callable(context=context, **execute_callable_kwargs)
             ^^^^^^^^^^^^^^^^^^^^^^^^^^^^^^^^^^^^^^^^^^^^^^^^^^^^^^^^^^^^^
  File "/home/airflow/.local/lib/python3.12/site-packages/airflow/models/taskinstance.py", line 432, in _execute_callable
    return execute_callable(context=context, **execute_callable_kwargs)
           ^^^^^^^^^^^^^^^^^^^^^^^^^^^^^^^^^^^^^^^^^^^^^^^^^^^^^^^^^^^^
  File "/home/airflow/.local/lib/python3.12/site-packages/airflow/models/baseoperator.py", line 400, in wrapper
    return func(self, *args, **kwargs)
           ^^^^^^^^^^^^^^^^^^^^^^^^^^^
  File "/home/airflow/.local/lib/python3.12/site-packages/airflow/operators/python.py", line 235, in execute
    return_value = self.execute_callable()
                   ^^^^^^^^^^^^^^^^^^^^^^^
  File "/home/airflow/.local/lib/python3.12/site-packages/airflow/operators/python.py", line 252, in execute_callable
    return self.python_callable(*self.op_args, **self.op_kwargs)
           ^^^^^^^^^^^^^^^^^^^^^^^^^^^^^^^^^^^^^^^^^^^^^^^^^^^^^
  File "/opt/airflow/dags/financial_etl_dag.py", line 79, in aggregate_monthly_summary
    cursor.execute("""
psycopg2.errors.UndefinedColumn: column "date" does not exist
LINE 4:             TO_CHAR(TO_DATE(date, 'YYYY-MM-DD'), 'YYYY-MM') ...
                                    ^

[2025-07-28T18:19:12.157+0000] {taskinstance.py:1205} INFO - Marking task as FAILED. dag_id=financial_etl_pipeline, task_id=aggregate_monthly_summary, execution_date=20250728T181903, start_date=20250728T181911, end_date=20250728T181912
[2025-07-28T18:19:12.169+0000] {standard_task_runner.py:110} ERROR - Failed to execute job 133 for task aggregate_monthly_summary (column "date" does not exist
LINE 4:             TO_CHAR(TO_DATE(date, 'YYYY-MM-DD'), 'YYYY-MM') ...
                                    ^
; 9513)
[2025-07-28T18:19:12.186+0000] {local_task_job_runner.py:240} INFO - Task exited with return code 1
[2025-07-28T18:19:12.201+0000] {taskinstance.py:3482} INFO - 0 downstream tasks scheduled from follow-on schedule check
[2025-07-28T18:19:12.204+0000] {local_task_job_runner.py:222} INFO - ::endgroup::
