[2025-07-28T18:18:34.998+0000] {local_task_job_runner.py:120} INFO - ::group::Pre task execution logs
[2025-07-28T18:18:35.031+0000] {taskinstance.py:2073} INFO - Dependencies all met for dep_context=non-requeueable deps ti=<TaskInstance: financial_etl_pipeline.aggregate_monthly_summary manual__2025-07-28T18:18:26+00:00 [queued]>
[2025-07-28T18:18:35.042+0000] {taskinstance.py:2073} INFO - Dependencies all met for dep_context=requeueable deps ti=<TaskInstance: financial_etl_pipeline.aggregate_monthly_summary manual__2025-07-28T18:18:26+00:00 [queued]>
[2025-07-28T18:18:35.043+0000] {taskinstance.py:2303} INFO - Starting attempt 1 of 1
[2025-07-28T18:18:35.385+0000] {taskinstance.py:2327} INFO - Executing <Task(PythonOperator): aggregate_monthly_summary> on 2025-07-28 18:18:26+00:00
[2025-07-28T18:18:35.447+0000] {logging_mixin.py:188} WARNING - /home/***/.local/lib/python3.12/site-packages/***/task/task_runner/standard_task_runner.py:61 DeprecationWarning: This process (pid=9477) is multi-threaded, use of fork() may lead to deadlocks in the child.
[2025-07-28T18:18:35.457+0000] {standard_task_runner.py:63} INFO - Started process 9479 to run task
[2025-07-28T18:18:35.435+0000] {standard_task_runner.py:90} INFO - Running: ['***', 'tasks', 'run', 'financial_etl_pipeline', 'aggregate_monthly_summary', 'manual__2025-07-28T18:18:26+00:00', '--job-id', '129', '--raw', '--subdir', 'DAGS_FOLDER/financial_etl_dag.py', '--cfg-path', '/tmp/tmppwq97rlt']
[2025-07-28T18:18:35.459+0000] {standard_task_runner.py:91} INFO - Job 129: Subtask aggregate_monthly_summary
[2025-07-28T18:18:35.881+0000] {task_command.py:426} INFO - Running <TaskInstance: financial_etl_pipeline.aggregate_monthly_summary manual__2025-07-28T18:18:26+00:00 [running]> on host c9a4a3294b33
[2025-07-28T18:18:36.519+0000] {taskinstance.py:2644} INFO - Exporting env vars: AIRFLOW_CTX_DAG_OWNER='***' AIRFLOW_CTX_DAG_ID='financial_etl_pipeline' AIRFLOW_CTX_TASK_ID='aggregate_monthly_summary' AIRFLOW_CTX_EXECUTION_DATE='2025-07-28T18:18:26+00:00' AIRFLOW_CTX_TRY_NUMBER='1' AIRFLOW_CTX_DAG_RUN_ID='manual__2025-07-28T18:18:26+00:00'
[2025-07-28T18:18:36.521+0000] {taskinstance.py:430} INFO - ::endgroup::
[2025-07-28T18:18:36.580+0000] {taskinstance.py:441} INFO - ::group::Post task execution logs
[2025-07-28T18:18:36.585+0000] {taskinstance.py:2890} ERROR - Task failed with exception
Traceback (most recent call last):
  File "/home/airflow/.local/lib/python3.12/site-packages/airflow/models/taskinstance.py", line 465, in _execute_task
    result = _execute_callable(context=context, **execute_callable_kwargs)
             ^^^^^^^^^^^^^^^^^^^^^^^^^^^^^^^^^^^^^^^^^^^^^^^^^^^^^^^^^^^^^
  File "/home/airflow/.local/lib/python3.12/site-packages/airflow/models/taskinstance.py", line 432, in _execute_callable
    return execute_callable(context=context, **execute_callable_kwargs)
           ^^^^^^^^^^^^^^^^^^^^^^^^^^^^^^^^^^^^^^^^^^^^^^^^^^^^^^^^^^^^
  File "/home/airflow/.local/lib/python3.12/site-packages/airflow/models/baseoperator.py", line 400, in wrapper
    return func(self, *args, **kwargs)
           ^^^^^^^^^^^^^^^^^^^^^^^^^^^
  File "/home/airflow/.local/lib/python3.12/site-packages/airflow/operators/python.py", line 235, in execute
    return_value = self.execute_callable()
                   ^^^^^^^^^^^^^^^^^^^^^^^
  File "/home/airflow/.local/lib/python3.12/site-packages/airflow/operators/python.py", line 252, in execute_callable
    return self.python_callable(*self.op_args, **self.op_kwargs)
           ^^^^^^^^^^^^^^^^^^^^^^^^^^^^^^^^^^^^^^^^^^^^^^^^^^^^^
  File "/opt/airflow/dags/financial_etl_dag.py", line 79, in aggregate_monthly_summary
    cursor.execute("""
psycopg2.errors.UndefinedColumn: column "date" does not exist
LINE 4:             TO_CHAR(TO_DATE(date, 'YYYY-MM-DD'), 'YYYY-MM') ...
                                    ^

[2025-07-28T18:18:36.632+0000] {taskinstance.py:1205} INFO - Marking task as FAILED. dag_id=financial_etl_pipeline, task_id=aggregate_monthly_summary, execution_date=20250728T181826, start_date=20250728T181835, end_date=20250728T181836
[2025-07-28T18:18:36.667+0000] {standard_task_runner.py:110} ERROR - Failed to execute job 129 for task aggregate_monthly_summary (column "date" does not exist
LINE 4:             TO_CHAR(TO_DATE(date, 'YYYY-MM-DD'), 'YYYY-MM') ...
                                    ^
; 9479)
[2025-07-28T18:18:36.687+0000] {local_task_job_runner.py:240} INFO - Task exited with return code 1
[2025-07-28T18:18:36.711+0000] {taskinstance.py:3482} INFO - 0 downstream tasks scheduled from follow-on schedule check
[2025-07-28T18:18:36.714+0000] {local_task_job_runner.py:222} INFO - ::endgroup::
