[2025-07-28T13:07:51.241+0000] {local_task_job_runner.py:120} INFO - ::group::Pre task execution logs
[2025-07-28T13:07:51.537+0000] {taskinstance.py:2073} INFO - Dependencies all met for dep_context=non-requeueable deps ti=<TaskInstance: financial_etl_dag.create_transactions_table scheduled__2025-06-01T00:00:00+00:00 [queued]>
[2025-07-28T13:07:51.550+0000] {taskinstance.py:2073} INFO - Dependencies all met for dep_context=requeueable deps ti=<TaskInstance: financial_etl_dag.create_transactions_table scheduled__2025-06-01T00:00:00+00:00 [queued]>
[2025-07-28T13:07:51.551+0000] {taskinstance.py:2303} INFO - Starting attempt 2 of 2
[2025-07-28T13:07:51.574+0000] {taskinstance.py:2327} INFO - Executing <Task(PostgresOperator): create_transactions_table> on 2025-06-01 00:00:00+00:00
[2025-07-28T13:07:51.591+0000] {logging_mixin.py:188} WARNING - /home/***/.local/lib/python3.12/site-packages/***/task/task_runner/standard_task_runner.py:61 DeprecationWarning: This process (pid=1400) is multi-threaded, use of fork() may lead to deadlocks in the child.
[2025-07-28T13:07:51.588+0000] {standard_task_runner.py:90} INFO - Running: ['***', 'tasks', 'run', 'financial_etl_dag', 'create_transactions_table', 'scheduled__2025-06-01T00:00:00+00:00', '--job-id', '113', '--raw', '--subdir', 'DAGS_FOLDER/financial_etl_dag.py', '--cfg-path', '/tmp/tmpsmrx7k6c']
[2025-07-28T13:07:51.594+0000] {standard_task_runner.py:63} INFO - Started process 1402 to run task
[2025-07-28T13:07:51.594+0000] {standard_task_runner.py:91} INFO - Job 113: Subtask create_transactions_table
[2025-07-28T13:07:51.687+0000] {task_command.py:426} INFO - Running <TaskInstance: financial_etl_dag.create_transactions_table scheduled__2025-06-01T00:00:00+00:00 [running]> on host 3fd530ef422e
[2025-07-28T13:07:51.825+0000] {taskinstance.py:2644} INFO - Exporting env vars: AIRFLOW_CTX_DAG_OWNER='***' AIRFLOW_CTX_DAG_ID='financial_etl_dag' AIRFLOW_CTX_TASK_ID='create_transactions_table' AIRFLOW_CTX_EXECUTION_DATE='2025-06-01T00:00:00+00:00' AIRFLOW_CTX_TRY_NUMBER='2' AIRFLOW_CTX_DAG_RUN_ID='scheduled__2025-06-01T00:00:00+00:00'
[2025-07-28T13:07:51.827+0000] {taskinstance.py:430} INFO - ::endgroup::
[2025-07-28T13:07:51.873+0000] {sql.py:276} INFO - Executing: CREATE TABLE IF NOT EXISTS transactions (
    transaction_id VARCHAR PRIMARY KEY,
    user_id VARCHAR,
    transaction_date TIMESTAMP,
    amount NUMERIC,
    category VARCHAR
);
[2025-07-28T13:07:51.889+0000] {base.py:84} INFO - Using connection ID 'postgres_default' for task execution.
[2025-07-28T13:07:51.911+0000] {base.py:84} INFO - Using connection ID 'postgres_default' for task execution.
[2025-07-28T13:07:51.922+0000] {taskinstance.py:441} INFO - ::group::Post task execution logs
[2025-07-28T13:07:51.923+0000] {taskinstance.py:2890} ERROR - Task failed with exception
Traceback (most recent call last):
  File "/home/airflow/.local/lib/python3.12/site-packages/airflow/models/taskinstance.py", line 465, in _execute_task
    result = _execute_callable(context=context, **execute_callable_kwargs)
             ^^^^^^^^^^^^^^^^^^^^^^^^^^^^^^^^^^^^^^^^^^^^^^^^^^^^^^^^^^^^^
  File "/home/airflow/.local/lib/python3.12/site-packages/airflow/models/taskinstance.py", line 432, in _execute_callable
    return execute_callable(context=context, **execute_callable_kwargs)
           ^^^^^^^^^^^^^^^^^^^^^^^^^^^^^^^^^^^^^^^^^^^^^^^^^^^^^^^^^^^^
  File "/home/airflow/.local/lib/python3.12/site-packages/airflow/models/baseoperator.py", line 400, in wrapper
    return func(self, *args, **kwargs)
           ^^^^^^^^^^^^^^^^^^^^^^^^^^^
  File "/home/airflow/.local/lib/python3.12/site-packages/airflow/providers/common/sql/operators/sql.py", line 282, in execute
    output = hook.run(
             ^^^^^^^^^
  File "/home/airflow/.local/lib/python3.12/site-packages/airflow/providers/common/sql/hooks/sql.py", line 397, in run
    with closing(self.get_conn()) as conn:
                 ^^^^^^^^^^^^^^^
  File "/home/airflow/.local/lib/python3.12/site-packages/airflow/providers/postgres/hooks/postgres.py", line 161, in get_conn
    self.conn = psycopg2.connect(**conn_args)
                ^^^^^^^^^^^^^^^^^^^^^^^^^^^^^
  File "/home/airflow/.local/lib/python3.12/site-packages/psycopg2/__init__.py", line 122, in connect
    conn = _connect(dsn, connection_factory=connection_factory, **kwasync)
           ^^^^^^^^^^^^^^^^^^^^^^^^^^^^^^^^^^^^^^^^^^^^^^^^^^^^^^^^^^^^^^^
psycopg2.OperationalError: connection to server at "postgres" (172.18.0.2), port 5432 failed: FATAL:  password authentication failed for user "postgres"

[2025-07-28T13:07:51.942+0000] {taskinstance.py:1205} INFO - Marking task as FAILED. dag_id=financial_etl_dag, task_id=create_transactions_table, execution_date=20250601T000000, start_date=20250728T130751, end_date=20250728T130751
[2025-07-28T13:07:51.964+0000] {standard_task_runner.py:110} ERROR - Failed to execute job 113 for task create_transactions_table (connection to server at "postgres" (172.18.0.2), port 5432 failed: FATAL:  password authentication failed for user "postgres"
; 1402)
[2025-07-28T13:07:52.011+0000] {local_task_job_runner.py:240} INFO - Task exited with return code 1
[2025-07-28T13:07:52.025+0000] {logging_mixin.py:188} WARNING - /home/***/.local/lib/python3.12/site-packages/***/models/baseoperator.py:1296 AirflowProviderDeprecationWarning: Call to deprecated class PostgresOperator. (Please use `***.providers.common.sql.operators.sql.SQLExecuteQueryOperator`.Also, you can provide `hook_params={'schema': <database>}`.)
[2025-07-28T13:07:52.042+0000] {taskinstance.py:3482} INFO - 0 downstream tasks scheduled from follow-on schedule check
[2025-07-28T13:07:52.051+0000] {local_task_job_runner.py:222} INFO - ::endgroup::
