[2025-07-28T12:51:15.594+0000] {local_task_job_runner.py:120} INFO - ::group::Pre task execution logs
[2025-07-28T12:51:16.266+0000] {taskinstance.py:2073} INFO - Dependencies all met for dep_context=non-requeueable deps ti=<TaskInstance: financial_etl_dag.load_to_postgres manual__2025-07-28T12:41:01.472973+00:00 [queued]>
[2025-07-28T12:51:16.316+0000] {taskinstance.py:2073} INFO - Dependencies all met for dep_context=requeueable deps ti=<TaskInstance: financial_etl_dag.load_to_postgres manual__2025-07-28T12:41:01.472973+00:00 [queued]>
[2025-07-28T12:51:16.317+0000] {taskinstance.py:2303} INFO - Starting attempt 2 of 2
[2025-07-28T12:51:16.383+0000] {taskinstance.py:2327} INFO - Executing <Task(PythonOperator): load_to_postgres> on 2025-07-28 12:41:01.472973+00:00
[2025-07-28T12:51:16.721+0000] {logging_mixin.py:188} WARNING - /home/***/.local/lib/python3.12/site-packages/***/task/task_runner/standard_task_runner.py:61 DeprecationWarning: This process (pid=670) is multi-threaded, use of fork() may lead to deadlocks in the child.
[2025-07-28T12:51:16.643+0000] {standard_task_runner.py:90} INFO - Running: ['***', 'tasks', 'run', 'financial_etl_dag', 'load_to_postgres', 'manual__2025-07-28T12:41:01.472973+00:00', '--job-id', '110', '--raw', '--subdir', 'DAGS_FOLDER/financial_etl_dag.py', '--cfg-path', '/tmp/tmpup5knl5n']
[2025-07-28T12:51:16.726+0000] {standard_task_runner.py:63} INFO - Started process 681 to run task
[2025-07-28T12:51:16.729+0000] {standard_task_runner.py:91} INFO - Job 110: Subtask load_to_postgres
[2025-07-28T12:51:18.271+0000] {task_command.py:426} INFO - Running <TaskInstance: financial_etl_dag.load_to_postgres manual__2025-07-28T12:41:01.472973+00:00 [running]> on host 3fd530ef422e
[2025-07-28T12:51:19.117+0000] {taskinstance.py:2644} INFO - Exporting env vars: AIRFLOW_CTX_DAG_OWNER='***' AIRFLOW_CTX_DAG_ID='financial_etl_dag' AIRFLOW_CTX_TASK_ID='load_to_postgres' AIRFLOW_CTX_EXECUTION_DATE='2025-07-28T12:41:01.472973+00:00' AIRFLOW_CTX_TRY_NUMBER='2' AIRFLOW_CTX_DAG_RUN_ID='manual__2025-07-28T12:41:01.472973+00:00'
[2025-07-28T12:51:19.143+0000] {taskinstance.py:430} INFO - ::endgroup::
[2025-07-28T12:51:19.237+0000] {taskinstance.py:441} INFO - ::group::Post task execution logs
[2025-07-28T12:51:19.241+0000] {taskinstance.py:2890} ERROR - Task failed with exception
Traceback (most recent call last):
  File "/home/airflow/.local/lib/python3.12/site-packages/airflow/models/taskinstance.py", line 465, in _execute_task
    result = _execute_callable(context=context, **execute_callable_kwargs)
             ^^^^^^^^^^^^^^^^^^^^^^^^^^^^^^^^^^^^^^^^^^^^^^^^^^^^^^^^^^^^^
  File "/home/airflow/.local/lib/python3.12/site-packages/airflow/models/taskinstance.py", line 432, in _execute_callable
    return execute_callable(context=context, **execute_callable_kwargs)
           ^^^^^^^^^^^^^^^^^^^^^^^^^^^^^^^^^^^^^^^^^^^^^^^^^^^^^^^^^^^^
  File "/home/airflow/.local/lib/python3.12/site-packages/airflow/models/baseoperator.py", line 400, in wrapper
    return func(self, *args, **kwargs)
           ^^^^^^^^^^^^^^^^^^^^^^^^^^^
  File "/home/airflow/.local/lib/python3.12/site-packages/airflow/operators/python.py", line 235, in execute
    return_value = self.execute_callable()
                   ^^^^^^^^^^^^^^^^^^^^^^^
  File "/home/airflow/.local/lib/python3.12/site-packages/airflow/operators/python.py", line 252, in execute_callable
    return self.python_callable(*self.op_args, **self.op_kwargs)
           ^^^^^^^^^^^^^^^^^^^^^^^^^^^^^^^^^^^^^^^^^^^^^^^^^^^^^
  File "/opt/airflow/dags/financial_etl_dag.py", line 64, in load_to_postgres
    df = pd.read_pickle(os.path.join(BASE_PATH, 'cleaned_data.pkl'))
         ^^^^^^^^^^^^^^^^^^^^^^^^^^^^^^^^^^^^^^^^^^^^^^^^^^^^^^^^^^^
  File "/home/airflow/.local/lib/python3.12/site-packages/pandas/io/pickle.py", line 189, in read_pickle
    with get_handle(
         ^^^^^^^^^^^
  File "/home/airflow/.local/lib/python3.12/site-packages/pandas/io/common.py", line 872, in get_handle
    handle = open(handle, ioargs.mode)
             ^^^^^^^^^^^^^^^^^^^^^^^^^
FileNotFoundError: [Errno 2] No such file or directory: '/opt/airflow/dags/files/cleaned_data.pkl'
[2025-07-28T12:51:19.358+0000] {taskinstance.py:1205} INFO - Marking task as FAILED. dag_id=financial_etl_dag, task_id=load_to_postgres, execution_date=20250728T124101, start_date=20250728T125116, end_date=20250728T125119
[2025-07-28T12:51:19.399+0000] {standard_task_runner.py:110} ERROR - Failed to execute job 110 for task load_to_postgres ([Errno 2] No such file or directory: '/opt/airflow/dags/files/cleaned_data.pkl'; 681)
[2025-07-28T12:51:19.628+0000] {local_task_job_runner.py:240} INFO - Task exited with return code 1
[2025-07-28T12:51:19.778+0000] {taskinstance.py:3482} INFO - 0 downstream tasks scheduled from follow-on schedule check
[2025-07-28T12:51:19.796+0000] {local_task_job_runner.py:222} INFO - ::endgroup::
